Workbook
Name _ctb１: '[1]現行DB一覧2(CT)'!$A$2:$E$220
Name assignee: Data!$H$1:$J$16
Name pc: "グループ 260"
Name フォロー１２: #REF!
Name 受入分＿エラーコード: #REF!
Name 受入分＿エラーメッセージ: #REF!
Name 受入分＿チェック: #REF!
Name 受入数量＿エラーコード: #REF!
Name 受入数量＿エラーメッセージ: #REF!
Name 受入数量＿チェック: #REF!
Name 受入日＿エラーコード: #REF!
Name 受入日＿エラーメッセージ: #REF!
Name 受入日＿チェック: #REF!
Name 受入時＿エラーコード: #REF!
Name 受入時＿エラーメッセージ: #REF!
Name 受入時＿チェック: #REF!
Name 受入開始終了日＿エラーコード: #REF!
Name 受入開始終了日＿エラーメッセージ: #REF!
Name 資料１: #REF!
Name 部門名: #REF!
Name 部門名: #REF!
Name 部門名: #REF!
Name 部門名: #REF!
Name 部門名: #REF!
Name 部門名: #REF!
Name 部門名: #REF!
Name 部門名: 表紙!$B$30
Name 部門名: #REF!

Sheet 表紙
A1: 出光興産株式会社 御中
B13: =改版履歴!A1&"対応 "&改版履歴!A1&"プログラムテスト仕様書兼成績書" -> CO00303D対応 CO00303Dプログラムテスト仕様書兼成績書
B25: ="第 "&MAX(改版履歴!A7:D38)&" 版" -> 第 1 版
B27: =MAX(改版履歴!AP7:AT38) -> 44294
B30: 株式会社システムエグゼ

Sheet 改版履歴
A1: CO00303D | E1: プログラムテスト仕様書兼成績書 | S1: システム名 | AE1: サブシステム名 | AQ1: 版数 | AU1: 作成日 | AZ1: 作成者
S2: 千葉運転管理システム | AE2: 充填口選択 | AQ2: =MAX(A7:D38) -> 1 | AU2: 44294 | AZ2: quoc-thang
A5: 改版履歴
A6: 版数 | E6: 分類 | H6: 変更箇所 | V6: 変更概要 | AP6: 改版日 | AU6: 更新者 | AZ6: 承認者
A7: 1 | E7: 新規 | H7: 第1版作成 | AP7: 44294 | AU7: quoc-thang

Sheet Summary
A1: 画面ID | E1: プログラムテスト仕様書兼成績書 | S1: システム名 | AE1: サブシステム名 | AQ1: 版数 | AU1: 作成日 | AZ1: 作成者
S2: 千葉運転管理システム | AQ2: =MAX(A7:D38) -> 1
A5: 改版履歴
A6: 版数 | E6: 分類 | H6: 変更箇所 | V6: 変更概要 | AP6: 改版日 | AU6: 更新者 | AZ6: 承認者
A7: 1 | E7: 新規 | H7: 第1版作成 | AP7: 44229 | AU7: TODO

Sheet 単体テスト項目書_充填口選択(CO00303D)
A1: =改版履歴!$A$1 -> CO00303D | F1: プログラムテスト仕様書兼成績書 （本体） | Y1: システム名 | AR1: サブシステム名 | BK1: 版数 | BO1: 作成日 | BS1: 作成者
Y2: 千葉運転管理システム | AR2: =改版履歴!$AE$2 -> 充填口選択 | BK2: 初版 | BO2: 44294 | BS2: quoc-thang
A4: ENGLISH
B5: プログラム名 | G5: CO00303D_充填口選択
A6: No | B6: =IF(A4="ENGLISH",Data!$B$21,Data!$C$21) -> Test Type | G6: =IF(A4="ENGLISH",Data!$B$33,Data!$C$33) -> Normal/ Abnormal | J6: =IF(A4="ENGLISH",Data!$B$24,Data!$C$24) -> Test Case Name | R6: =IF(A4="ENGLISH",Data!$B$25,Data!$C$25) -> Pre-condition/ Set up | Z6: =IF(A4="ENGLISH",Data!$B$27,Data!$C$27) -> Expected Result | AL6: =IF(A4="ENGLISH",Data!$B$28,Data!$C$28) -> Test Step/Test Case details | AU6: =IF(A4="ENGLISH",Data!$B$29,Data!$C$29) -> Verify Property | AX6: =IF(A4="ENGLISH",Data!$B$12,Data!$C$12) -> Test By | BB6: =IF(A4="ENGLISH",Data!$B$11,Data!$C$11) -> Times | BC6: =IF(A4="ENGLISH",Data!$B$13,Data!$C$13) -> Test Date | BG6: =IF(A4="ENGLISH",Data!$B$30,Data!$C$30) -> Test Result | BJ6: =IF(A4="ENGLISH",Data!$B$32,Data!$C$32) -> Error Cause | BM6: =IF(A4="ENGLISH",Data!$B$14,Data!$C$14) -> Finish Date | BQ6: =IF(A4="ENGLISH",Data!$B$31,Data!$C$31) -> Remarks
A8: =(ROW()-3)/5 -> 1 | B8: ①画面デザインチェックリスト | G8: 正常/Normal | J8: 画面デザインチェック | R8: 「CO00303D_充填口選択」画面を表示する。 | Z8: 「①画面デザインチェックリスト」表の記述と一致されること。 | AL8: 現新比較⇒画面ショット | BB8: 1 | BG8: －
BB9: 2
AX10: quoc-thang | BB10: 3
BB11: 4
BB12: 5
A13: =(ROW()-3)/5 -> 2 | B13: ②画面動作チェックリスト＆④イベント別コントロール動作 | G13: 正常/Normal | J13: 画面動作&イベント別コントロール動作チェック | R13: 「CO00303D_充填口選択」画面を表示する。 | Z13: 「②画面動作チェックリスト＆④イベント別コントロール動作」表の記述と一致されること。 | AL13: 現新比較⇒画面ショット | BB13: 1
BB14: 2
AX15: quoc-thang | BB15: 3
BB16: 4
BB17: 5
A18: =(ROW()-3)/5 -> 3 | B18: ③コントロールチェックリスト | G18: 正常/Normal | J18: コントロールチェック | R18: 「CO00303D_充填口選択」画面を表示する。 | Z18: 「③コントロールチェックリスト」表の記述と一致されること。 | AL18: 現新比較⇒画面ショット | BB18: 1
BB19: 2
AX20: quoc-thang | BB20: 3
BB21: 4
BB22: 5
A23: =(ROW()-3)/5 -> 4 | B23: ⑤イベント別バリデーション、パターン別業務処理 | G23: 正常/Normal | J23: イベント別バリデーション、パターン別業務処理チェック | R23: 「CO00303D_充填口選択」画面を表示する。 | Z23: 「⑤イベント別バリデーション、パターン別業務処理」表の記述と一致されること。 | AL23: 現新比較⇒画面ショット | BB23: 1
BB24: 2
AX25: quoc-thang | BB25: 3
BB26: 4
BB27: 5
A28: =(ROW()-3)/5 -> 5 | BB28: 1
BB29: 2
BB30: 3
BB31: 4
BB32: 5
A33: =(ROW()-3)/5 -> 6 | BB33: 1
BB34: 2
BB35: 3
BB36: 4
BB37: 5
A38: =(ROW()-3)/5 -> 7 | BB38: 1
BB39: 2
BB40: 3
BB41: 4
BB42: 5
...

Sheet ①画面デザインチェックリスト
B6: << 戻る
AF9: ⚫：OK
AF10: ✕：NG
B11: No. | C11: コントロール↓ | M11: プロパティ↓ | AF11: ―：不適用 | AN11: コントロール↓ | AW11: プロパティ↓
B12: =IF(C12<>"",MAX($B$4:INDIRECT("B"&ROW()-1))+1,"") -> 1 | C12: フォーム | Z12: 画面イメージ 現新比較 | AF12: テスト結果
B13: =IF(C13<>"",MAX($B$4:INDIRECT("B"&ROW()-1))+1,"") | M13: 表示位置 | AF13: ●
B14: =IF(C14<>"",MAX($B$4:INDIRECT("B"&ROW()-1))+1,"") | M14: サイズ | AF14: ●
B15: =IF(C15<>"",MAX($B$4:INDIRECT("B"&ROW()-1))+1,"") | M15: 背景色 | AF15: ●
B16: =IF(C16<>"",MAX($B$4:INDIRECT("B"&ROW()-1))+1,"") | M16: コントロールボックス | AF16: ●
B17: =IF(C17<>"",MAX($B$4:INDIRECT("B"&ROW()-1))+1,"")
B18: =IF(C18<>"",MAX($B$4:INDIRECT("B"&ROW()-1))+1,"") -> 2 | C18: テキスト | AN18: テキスト | BD18: コントロール別現新比較 | BL18: テスト結果
B19: =IF(C19<>"",MAX($B$4:INDIRECT("B"&ROW()-1))+1,"") | M19: 表示位置 | AF19: － | AX19: 文字数 | BL19: －
B20: =IF(C20<>"",MAX($B$4:INDIRECT("B"&ROW()-1))+1,"") | M20: サイズ | AF20: －
B21: =IF(C21<>"",MAX($B$4:INDIRECT("B"&ROW()-1))+1,"") | M21: 背景色 | AF21: －
B22: =IF(C22<>"",MAX($B$4:INDIRECT("B"&ROW()-1))+1,"") | M22: フォント | AF22: －
B23: =IF(C23<>"",MAX($B$4:INDIRECT("B"&ROW()-1))+1,"") | M23: 配置（右・左・中央） | AF23: －
B24: =IF(C24<>"",MAX($B$4:INDIRECT("B"&ROW()-1))+1,"") | M24: 文字数 | AF24: －
B25: =IF(C25<>"",MAX($B$4:INDIRECT("B"&ROW()-1))+1,"") | M25: マスク | AF25: －
B26: =IF(C26<>"",MAX($B$4:INDIRECT("B"&ROW()-1))+1,"") | M26: フォーマット | AF26: －
B27: =IF(C27<>"",MAX($B$4:INDIRECT("B"&ROW()-1))+1,"")
B28: =IF(C28<>"",MAX($B$4:INDIRECT("B"&ROW()-1))+1,"") -> 3 | C28: チェックボックス
B29: =IF(C29<>"",MAX($B$4:INDIRECT("B"&ROW()-1))+1,"") | M29: 表示位置 | AF29: －
B30: =IF(C30<>"",MAX($B$4:INDIRECT("B"&ROW()-1))+1,"") | M30: サイズ | AF30: －
B31: =IF(C31<>"",MAX($B$4:INDIRECT("B"&ROW()-1))+1,"") | M31: 背景色 | AF31: －
B32: =IF(C32<>"",MAX($B$4:INDIRECT("B"&ROW()-1))+1,"") | M32: フォント | AF32: －
B33: =IF(C33<>"",MAX($B$4:INDIRECT("B"&ROW()-1))+1,"") | M33: 配置 | AF33: －
B34: =IF(C34<>"",MAX($B$4:INDIRECT("B"&ROW()-1))+1,"") | M34: デフォルト | AF34: －
B35: =IF(C35<>"",MAX($B$4:INDIRECT("B"&ROW()-1))+1,"")
B36: =IF(C36<>"",MAX($B$4:INDIRECT("B"&ROW()-1))+1,"") -> 4 | C36: オプションボタン
B37: =IF(C37<>"",MAX($B$4:INDIRECT("B"&ROW()-1))+1,"") | M37: 表示位置 | AF37: ●
B38: =IF(C38<>"",MAX($B$4:INDIRECT("B"&ROW()-1))+1,"") | M38: サイズ | AF38: ●
B39: =IF(C39<>"",MAX($B$4:INDIRECT("B"&ROW()-1))+1,"") | M39: 背景色 | AF39: ●
B40: =IF(C40<>"",MAX($B$4:INDIRECT("B"&ROW()-1))+1,"") | M40: フォント | AF40: ●
B41: =IF(C41<>"",MAX($B$4:INDIRECT("B"&ROW()-1))+1,"") | M41: 配置 | AF41: ●
B42: =IF(C42<>"",MAX($B$4:INDIRECT("B"&ROW()-1))+1,"") | M42: デフォルト | AF42: ●
B43: =IF(C43<>"",MAX($B$4:INDIRECT("B"&ROW()-1))+1,"")
B44: =IF(C44<>"",MAX($B$4:INDIRECT("B"&ROW()-1))+1,"") -> 5 | C44: コンボボックス | AN44: コンボボックス | BD44: コントロール別現新比較 | BL44: テスト結果
B45: =IF(C45<>"",MAX($B$4:INDIRECT("B"&ROW()-1))+1,"") | M45: 表示位置 | AF45: － | AX45: 表示順 | BL45: －
B46: =IF(C46<>"",MAX($B$4:INDIRECT("B"&ROW()-1))+1,"") | M46: サイズ | AF46: －
B47: =IF(C47<>"",MAX($B$4:INDIRECT("B"&ROW()-1))+1,"") | M47: 背景色 | AF47: －
...

Sheet No1_1
B2: VB6 | L2: VB.NET
B4: フォーム | L4: フォーム

Sheet No1_4
B2: VB6 | L2: VB.NET
B4: オプションボタン | L4: オプションボタン
B93: 1. 20L充填機
B145: 2. 4L充填機
B197: 3. タンカー入出荷アーム
B249: 4. 1KLバルク充填機
B301: 5. ドラム充填機
B353: 6. ローリー積口
B405: 7. 添加剤ローリー受入口
B457: 8. すべて

Sheet No1_7
B2: VB6
B4: 充填口マスタ一覧

Sheet No1_8
B2: VB6 | L2: VB.NET
B4: ボタン | L4: ボタン
B95: 1. 戻る
B147: 2. 選択

Sheet No1_9
B2: VB6 | L2: VB.NET
B4: ラベル | L4: ラベル
B94: 1. 画面タイトル
B150: 2. 一覧タイトル

Sheet ②画面動作チェックリスト＆④イベント別コントロール動作
Q7: ②画面動作チェックリスト | T7: ④イベント別コントロール動作
Q9: ※油種コード入力後 | T9: ◯：入力可 ✕：入力不可
A10: No | B10: 項目↓ Item | K10: コントロール↓ Control | Q10: 入力順/Input oder | T10: Init Screen
A12: 1 | B12: 20L充填機 | K12: オプションボタン | Q12: 1 | T12: ◯
A13: 2 | B13: 4L充填機 | K13: オプションボタン | Q13: 2 | T13: ◯
A14: 3 | B14: タンカー入出荷アーム | K14: オプションボタン | Q14: 3 | T14: ◯
A15: 4 | B15: 1KLバルク充填機 | K15: オプションボタン | Q15: 4 | T15: ◯
A16: 5 | B16: ドラム充填機 | K16: オプションボタン | Q16: 5 | T16: ◯
A17: 6 | B17: ローリー積口 | K17: オプションボタン | Q17: 6 | T17: ◯
A18: 7 | B18: 添加剤ローリー受入口 | K18: オプションボタン | Q18: 7 | T18: ◯
A19: 8 | B19: すべて | K19: オプションボタン | Q19: 8 | T19: ◯
A21: 9 | B21: 充填口マスタ一覧 | K21: データグリッドビュー | Q21: 9 | T21: ◯
A23: 10 | B23: 戻る | K23: ボタン | Q23: 10 | T23: ◯
A24: 11 | B24: 選択 | K24: ボタン | Q24: 11 | T24: ◯
K26: No. | Q26: ②No1 | T26: ④No1
K27: テスト結果 | T27: ◯

Sheet No4_1
B2: VB6 | L2: VB.NET
B4: ○：入力可 ×：入力不可 | L4: ○：入力可 ×：入力不可

Sheet ③コントロールチェックリスト
B6: << 戻る | BY6: コンボボックス／リストボックス | CL6: オプションボタン／チェックボックス
AQ7: テキスト／データグリッドビュー内テキスト
B8: No. | C8: 項目↓ Item | L8: コントロール↓ Control | S8: 書式/Format | X8: 桁数/Number's Digits | AD8: 必須 Required | AF8: 初期値/Initial | AL8: テスト結果 | AQ8: NULL | AT8: MAX | AW8: MIN | AZ8: 禁則 | BC8: １桁 | BF8: MAX+1 | BI8: MIN-1 | BL8: 数値項目に文字 | BP8: 全角項目に半角 | BT8: 半角項目に全角 | BY8: 未選択 | CB8: 先頭選択 | CE8: 最終選択 | CH8: 手入力 | CL8: 未選択 Unselected | CO8: 選択 Choice
X9: 整数 | AA9: 小数
B10: =IF(C10<>"",MAX($B$4:INDIRECT("B"&ROW()-1))+1,"-") -> 1 | C10: 20L充填機 | L10: オプションボタン | S10: - | X10: - | AA10: - | AD10: - | AF10: -
B11: =IF(C11<>"",MAX($B$4:INDIRECT("B"&ROW()-1))+1,"-") -> 2 | C11: 4L充填機 | L11: オプションボタン | S11: - | X11: - | AA11: - | AD11: - | AF11: -
B12: =IF(C12<>"",MAX($B$4:INDIRECT("B"&ROW()-1))+1,"-") -> 3 | C12: タンカー入出荷アーム | L12: オプションボタン | S12: - | X12: - | AA12: - | AD12: - | AF12: -
B13: =IF(C13<>"",MAX($B$4:INDIRECT("B"&ROW()-1))+1,"-") -> 4 | C13: 1KLバルク充填機 | L13: オプションボタン | S13: - | X13: - | AA13: - | AD13: - | AF13: -
B14: =IF(C14<>"",MAX($B$4:INDIRECT("B"&ROW()-1))+1,"-") -> 5 | C14: ドラム充填機 | L14: オプションボタン | S14: - | X14: - | AA14: - | AD14: - | AF14: -
B15: =IF(C15<>"",MAX($B$4:INDIRECT("B"&ROW()-1))+1,"-") -> 6 | C15: ローリー積口 | L15: オプションボタン | S15: - | X15: - | AA15: - | AD15: - | AF15: -
B16: =IF(C16<>"",MAX($B$4:INDIRECT("B"&ROW()-1))+1,"-") -> 7 | C16: 添加剤ローリー受入口 | L16: オプションボタン | S16: - | X16: - | AA16: - | AD16: - | AF16: -
B17: =IF(C17<>"",MAX($B$4:INDIRECT("B"&ROW()-1))+1,"-") -> 8 | C17: すべて | L17: オプションボタン | S17: - | X17: - | AA17: - | AD17: - | AF17: -
B19: =IF(C19<>"",MAX($B$4:INDIRECT("B"&ROW()-1))+1,"-") -> 9 | C19: 充填口マスタ一覧 | L19: データグリッドビュー | S19: - | X19: - | AA19: - | AD19: - | AF19: DBの現在日付
B21: =IF(C21<>"",MAX($B$4:INDIRECT("B"&ROW()-1))+1,"-") -> 10 | C21: 戻る | L21: ボタン | S21: - | X21: - | AA21: - | AD21: - | AF21: - | AL21: 〇
B22: =IF(C22<>"",MAX($B$4:INDIRECT("B"&ROW()-1))+1,"-") -> 11 | C22: 確定 | L22: ボタン | S22: - | X22: - | AA22: - | AD22: - | AF22: - | AL22: 〇
AL23: 〇：OK
AL24: ✕：NG
AL25: ―：不適用

Sheet ⑤イベント別バリデーション、パターン別業務処理
B6: << 戻る
C8: イベントの業務処理
B9: No. | C9: 条件 | AG9: イベント | AM9: 結果 | BD9: テスト結果
C10: 処理区分 | H10: 項目 | S10: その他項目/Other condition
B11: 1 | C11: 初期表示 | AG11: 起動時 | AM11: All of the data in [充填口マスタ一覧] dataGridView are displayed
B12: 2 | C12: 「充填口区分」ボタン押下 | H12: Button [20L充填機] | AG12: 切り替え | AM12: The data that matches "filling port classification" = 'DM' is displayed
B13: 3 | H13: Button [4L充填機] | AG13: 切り替え | AM13: The data that matches "filling port classification" = '4L' is displayed
B14: 4 | H14: Button [タンカー入出荷アーム] | AG14: 切り替え | AM14: The data that matches "filling port classification" = '20L' is displayed
B15: 5 | H15: Button [1Kバルク充填機] | AG15: 切り替え | AM15: The data that matches "filling port classification" = 'BC' is displayed
B16: 6 | H16: Button [ドラム充填機] | AG16: 切り替え | AM16: The data that matches "filling port classification" = 'AM' is displayed
B17: 7 | H17: Button [ローリー積口] | AG17: 切り替え | AM17: The data that matches "filling port classification" = 'TL1' is displayed
B18: 8 | H18: Button [添加剤ローリー受入口] | AG18: 切り替え | AM18: The data that matches "filling port classification" = 'TL2' is displayed
B19: 9 | H19: Button [すべて] | AG19: 切り替え | AM19: All of the data in [充填口マスタ一覧] dataGridView are displayed
B20: 10 | C20: Acquiring the data of [充填口マスタ] from the selected row in dataGridView | H20: Button「選択」 | S20: There is data in dataGridView One row in dataGridView is selected | AG20: ボタン押下 | AM20: Acquires the "filling port No." of the selected row Search for "filling port master" based on the acquired "filling port No." value. The acquired "filling port" data is stored in the return parameter and close the form
B21: 11 | C21: Closing the form | H21: Button 「戻る」 | AG21: ボタン押下 | AM21: The form is closed
C23: データグリッドビュー動作
B24: No. | C24: 条件 | AG24: イベント | AM24: 結果 | BD24: テスト結果
B26: 12 | C26: A row in dataGridView is selected | AG26: 行選択 | AM26: Change the background color of the selected row
B27: 13 | C27: A row in dataGridView is double-click | AG27: 行選択 | AM27: The acquired "filling port" data that correspond to the selected row is stored in the return parameter.
C29: ＤＢ取得結果
B30: No. | C30: 条件 | AG30: イベント | AM30: 結果 | BD30: SQL現新比較 | BH30: テスト結果
B32: 14 | C32: データ無し | G32: There is no data in table [充填口マスタ ] | AG32: 「一覧表示」 | AM32: An empty list is displayed in the dataGridView | BD32: 参照SQLが現新比較で一致すること
B33: 15 | C33: データあり | G33: There is data in table [充填口マスタ ] | AG33: 「一覧表示」 | AM33: The data in the database is reflected as a list in the dataGridView is stored in the return parameter. | BD33: 参照SQLが現新比較で一致すること
C35: 異常系
B36: No. | C36: 条件 | AG36: イベント | AM36: 結果 | BD36: テスト結果
B38: 16 | C38: VSデバッグにて、手動にて例外を発生させる | AG38: 「一覧表示」 | AM38: エラーメッセージが表示されること。 例外が発生する時にアプリケーションが停止されないこと。
C40: 排他制御
B41: No. | C41: 条件 | AG41: イベント | AM41: 結果 | BD41: テスト結果
B43: 16 | C43: 同一クライアントPCにてCO00303Dを二重起動する。 | AG43: 初期 | AM43: 「同一のプログラムが既に実行されています。」メッセージが表示されること。 例外が発生する時にアプリケーションが停止されないこと。
C45: 性能測定
B46: No. | C46: 条件 | AG46: イベント | AM46: 結果 | BD46: テスト結果
B48: 16 | C48: Processing time before and after the form is loaded | AG48: 「一覧表示」 | AM48: ボタン押下前後の処理時間の現新比較を行う。 新システムで処理時間は少なくとも現システムより遅くないようにする。 例外が発生する時にアプリケーションが停止されないこと。

Sheet Data
B1: ENGLISH | C1: JAPANESE | E1: Id | F1: ENGLISH | G1: JAPANESE | H1: Id | I1: Assignee
B2: Unit Test Case | C2: 単体テスト仕様書・結果 | E2: 1 | F2: ①Screen Design Checklist | G2: ①画面デザインチェックリスト | H2: 1 | I2: quang-thien
B3: Project ID | C3: プロジェクトＩＤ | E3: 2 | F3: ②Screen Operation Checklist | G3: ②画面動作チェックリスト | H3: 2 | I3: kieu-trinh
B4: Project Name | C4: プロジェクト名 | E4: 3 | F4: ③Control Checklist | G4: ③コントロールチェックリスト | H4: 3 | I4: duong-viet
B5: Screen / Function Name | C5: 画面名・機能名 | E5: 4 | F5: ④Event Control | G5: ④イベント別コントロール動作 | H5: 4 | I5: tuan-vu
B6: Create | C6: 作成 | E6: 5 | F6: ⑤Validation, Business Processing | G6: ⑤イベント別バリデーション、パターン別業務処理
B7: Review | C7: レビュー
B8: Approved | C8: 承認
B9: Name | C9: 名前
B10: Date | C10: 日付
B11: Times | C11: 回
B12: Test By | C12: 担当者
B13: Test Date | C13: 実施日
B14: Finish Date | C14: 完了日
B15: OK | C15: OK
B16: High | C16: 高
B17: Medium | C17: 中
B18: Low | C18: 低
... B57: Defect # | C57: 不具合 #

Sheet ①画面ID_No_XX

Sheet ②④画面ID_No_XX

Sheet ③画面ID_No_XX

Sheet ⑤画面ID_No_XX
